Workbook

Sheet Leyenda
A1: Priorización RICE y Backlog — Agente de sugerencias estilísticas para Innosoft
A2: Versión 1.1 · 29-sep-2026 (replanificación) · Versión 1.0 · 11-sep-2026 · Documento asociado: catalogo_requisitos_innosoft.md
A4: Hoja | B4: Contenido
A5: RICE | B5: Todas las historias del backlog con Reach, Impact, Confidence y Effort. El Score se calcula con fórmula. Las celdas azules son entradas editables; al cambiarlas, Score y Ranking se recalculan.
A6: Sprint 1 | B6: Registro del Sprint 1 (14 al 25 de septiembre): lo comprometido y su resultado real.
A7: Tareas Sprint 1 | B7: Sprint Backlog: tareas por historia con estado editable (Pendiente / En curso / Hecho). El avance del sprint se calcula con fórmula.
A8: Calendario | B8: Sprints de 2 semanas, tema de cada uno según el Capítulo III y eventos Scrum del Sprint 1.
A9: Replan 29-sep | B9: Replanificación: plan por sprint, alcances reducidos, historias sacadas del plan, orden de recorte y puntos de control.
A10: Sprint 2 | B10: Historias comprometidas para el Sprint 2 (28-sep al 9-oct), con el objetivo original del Sprint 1.
A11: Tareas Sprint 2 | B11: Sprint Backlog del Sprint 2 con estado editable y avance calculado.
A13: Escalas RICE | B13: Definición
A14: Reach (R) | B14: Porcentaje de envíos a Innosoft en un semestre que se beneficiarían de la historia (0 a 100).
A15: Impact (I) | B15: 3 = masivo · 2 = alto · 1 = medio · 0,5 = bajo · 0,25 = mínimo.
A16: Confidence (C) | B16: 1,00 = alta (100 %) · 0,80 = media · 0,50 = baja. Refleja incertidumbre técnica o de requisitos.
... A21: Colores | B21: Azul = entrada editable · Negro = fórmula · Fondo amarillo = celda que debe actualizar el equipo.

Sheet Replan 29-sep
A1: Replanificación del 29-sep-2026
A2: Motivo: el Sprint 1 (14–25 sep) produjo especificación y diseño, pero no código. Quedan 5 sprints (2 a 6) hasta el 4-dic.
A4: 1. Plan por sprint
A5: Sprint | B5: Fechas | C5: Inicio | D5: Fin | E5: Historias | F5: Effort RICE | G5: Meta
A6: 2 | B6: =TEXT(C6,"dd-mmm")&" al "&TEXT(D6,"dd-mmm") | C6: 46294 | D6: 46304 | E6: US-00, US-01, US-04, US-09, US-06, US-10 | F6: =SUMIF(RICE!$K$5:$K$40,A6,RICE!$G$5:$G$40)+0.5 | G6: Walking skeleton en Docker con RE-20/RE-21
A7: 3 | B7: =TEXT(C7,"dd-mmm")&" al "&TEXT(D7,"dd-mmm") | C7: 46307 | D7: 46318 | E7: US-03, US-05*, US-07, US-08*, US-11*, US-12, US-13* + spike OJS | F7: =SUMIF(RICE!$K$5:$K$40,A7,RICE!$G$5:$G$40) | G7: Citas y referencias IEEE detectadas; decisión técnica sobre OJS
A8: 4 | B8: =TEXT(C8,"dd-mmm")&" al "&TEXT(D8,"dd-mmm") | C8: 46321 | D8: 46332 | E8: US-17, US-15, US-16, US-18*, US-28, US-19, US-20 | F8: =SUMIF(RICE!$K$5:$K$40,A8,RICE!$G$5:$G$40) | G8: Sugerencias con Gemini anonimizadas y visibles para el editor
A9: 5 | B9: =TEXT(C9,"dd-mmm")&" al "&TEXT(D9,"dd-mmm") | C9: 46335 | D9: 46346 | E9: US-21, US-24, US-02 | F9: =SUMIF(RICE!$K$5:$K$40,A9,RICE!$G$5:$G$40) | G9: Flujo completo: OJS → agente → editor → comentario en OJS
A10: 6 | B10: =TEXT(C10,"dd-mmm")&" al "&TEXT(D10,"dd-mmm") | C10: 46349 | D10: 46360 | E10: Sin historias nuevas | F10: =SUMIF(RICE!$K$5:$K$40,A10,RICE!$G$5:$G$40) | G10: Buffer, evaluación (precisión, recall, F1, aceptación), manuales, tesis
E11: Total R1 planificado (effort RICE) | F11: =SUM(F6:F10)
E12: Promedio por sprint de desarrollo (2 a 5) | F12: =AVERAGE(F6:F9)
E13: Referencia: plan original, promedio por sprint (dato del plan del 11-sep) | F13: 3.75 | G13: 22,5 unidades RICE en 6 sprints (plan original); introducido a mano, no se recalcula.
E14: Carga extra vs. plan original | F14: =IF(F13>0,F12/F13-1,0)
A15: * Alcance reducido: ver sección 2. El effort RICE no se reduce para no alterar el ranking; la reducción es margen de seguridad.
A17: 2. Historias con alcance reducido (MVP de tesis)
A18: ID | B18: Historia | E18: Qué entra en el MVP / qué pasa a R2
A19: US-05 | B19: Detectar secciones IMRyD | E19: Alcance MVP: solo Resumen, Palabras clave y Referencias; diccionario completo de variantes en R2.
A20: US-08 | B20: Extraer lista de referencias | E20: Alcance MVP: segmentación y numeración de entradas; parseo por campos en R2.
A21: US-11 | B21: Validar figuras: pie, numeración, orden (RE-23..25) | E21: Alcance MVP: RE-23 y RE-24; RE-25 (mención en el texto) en R2.
A22: US-13 | B22: Validar referencias IEEE (RE-44..49) | E22: Alcance MVP: RE-44, RE-46, RE-47 y RE-49; patrón IEEE por tipo (RE-45) y RE-48 en R2.
A23: US-18 | B23: Reintentos, límite de tokens y fallback | E23: Alcance MVP: reintentos con backoff y fallback; presupuesto de tokens en R2.
A25: 3. Sacadas del plan (quedan en el backlog para después de la tesis)
A26: ID | B26: Historia | C26: Release | D26: Antes | E26: Motivo
A27: US-14 | B27: Validar estructura, resumen y palabras clave (RE-01..15) | C27: =RICE!J34 | D27: Sprint 3 | E27: Reglas de estructura con alto componente LLM; se prioriza figuras y referencias.
A28: US-29 | B28: Registro de consumo y latencia de Gemini | C28: =RICE!J16 | D28: Sprint 4 | E28: US-28 cubre la medición necesaria para RNF-03.
A29: US-22 | B29: Agregar sugerencia manual | C29: =RICE!J29 | D29: Sprint 6 | E29: Sprint 6 se dedica a evaluación.
A30: US-23 | B30: Marcar manuscrito como "sin observaciones" | C30: =RICE!J32 | D30: Sprint 6 | E30: Solo si sobra capacidad (0,25).
A31: US-25 | B31: Reintento y cola si OJS no responde | C31: =RICE!J38 | D31: Sprint 6 | E31: Riesgo bajo (Reach 5).
A32: US-27 | B32: Notificar al editor por correo OJS | C32: =RICE!J27 | D32: Sprint 6 | E32: El editor usa la cola de revisión.
A34: 4. Orden de recorte si vuelve a haber retraso
A35: 1 | B35: US-02 (plugin): disparar el análisis manualmente vía POST /manuscripts; se mantiene la publicación en OJS (US-24).
A36: 2 | B36: US-11 completa pasa a R2 (se pierde RE-23/RE-24).
A37: 3 | B37: US-13 se limita a RE-44 y RE-46.
A38: 4 | B38: US-20 muestra evidencia solo en texto (sin miniaturas).
A39: 5 | B39: Si el 9-oct no hay walking skeleton: reunión con el asesor para redefinir el alcance de la tesis.
A41: 5. Puntos de control
A42: Fecha | E42: Qué debe existir
A43: 46295 | C43: Specs del Sprint 2 aprobadas (00-producto, formato-reglas, US-00/01/04/06/09/10).
A44: 46297 | C44: Repositorio con CI verde y docker compose up funcionando.
A45: 46304 | C45: Demo del walking skeleton (Sprint Review 2).
...

Sheet RICE
A1: Priorización RICE del Product Backlog
A2: Score = Reach × Impact × Confidence / Effort. Edite solo las celdas azules. Columna 'Sprint previsto' actualizada en la replanificación del 29-sep-2026 (ver hoja 'Replan 29-sep').
A4: ID | B4: Épica | C4: Historia | D4: Reach (0-100) | E4: Impact | F4: Confidence | G4: Effort | H4: Score | I4: Ranking | J4: Release | K4: Sprint previsto | L4: Justificación breve
A5: US-01 | B5: A. Recepción | C5: Recibir PDF por API | D5: 100 | E5: 3 | F5: 1 | G5: 0.5 | H5: =IF(G5>0,D5*E5*F5/G5,0) | I5: =RANK(H5,$H$5:$H$40,0) | J5: R1 | K5: 2 | L5: Punto de entrada de todo el flujo.
A6: US-04 | B6: B. Extracción | C6: Extraer texto y páginas | D6: 100 | E6: 3 | F6: 1 | G6: 0.5 | H6: =IF(G6>0,D6*E6*F6/G6,0) | I6: =RANK(H6,$H$5:$H$40,0) | J6: R1 | K6: 2 | L6: Sin texto no hay reglas.
A7: US-09 | B7: C. Validación | C7: Cargar reglas Innosoft desde YAML | D7: 100 | E7: 3 | F7: 1 | G7: 0.5 | H7: =IF(G7>0,D7*E7*F7/G7,0) | I7: =RANK(H7,$H$5:$H$40,0) | J7: R1 | K7: 2 | L7: Habilita el motor completo; reglas versionadas.
A8: US-16 | B8: D. Sugerencias | C8: Validar esquema de respuesta del LLM | D8: 100 | E8: 2 | F8: 1 | G8: 0.5 | H8: =IF(G8>0,D8*E8*F8/G8,0) | I8: =RANK(H8,$H$5:$H$40,0) | J8: R1 | K8: 4 | L8: Protege la trazabilidad regla→sugerencia.
A9: US-07 | B9: B. Extracción | C9: Extraer citas en texto [n] | D9: 100 | E9: 2 | F9: 0.8 | G9: 0.5 | H9: =IF(G9>0,D9*E9*F9/G9,0) | I9: =RANK(H9,$H$5:$H$40,0) | J9: R1 | K9: 3 | L9: Barato y necesario para citas IEEE.
A10: US-17 | B10: D. Sugerencias | C10: Anonimizar contexto antes de enviar al LLM | D10: 100 | E10: 2 | F10: 0.8 | G10: 0.5 | H10: =IF(G10>0,D10*E10*F10/G10,0) | I10: =RANK(H10,$H$5:$H$40,0) | J10: R1 | K10: 4 | L10: Requisito legal (Ley 29733).
A11: US-12 | B11: C. Validación | C11: Validar citas IEEE en texto (RE-40..43) | D11: 80 | E11: 2 | F11: 0.8 | G11: 0.5 | H11: =IF(G11>0,D11*E11*F11/G11,0) | I11: =RANK(H11,$H$5:$H$40,0) | J11: R1 | K11: 3 | L11: Segundo dolor principal (citas).
A12: US-06 | B12: B. Extracción | C12: Extraer figuras: posición, tamaño, pie | D12: 90 | E12: 3 | F12: 0.8 | G12: 1 | H12: =IF(G12>0,D12*E12*F12/G12,0) | I12: =RANK(H12,$H$5:$H$40,0) | J12: R1 | K12: 2 | L12: Dolor principal de la revista (figuras).
A13: US-10 | B13: C. Validación | C13: Validar figuras: tamaño y proporción (RE-20, RE-21) | D13: 90 | E13: 3 | F13: 0.8 | G13: 1 | H13: =IF(G13>0,D13*E13*F13/G13,0) | I13: =RANK(H13,$H$5:$H$40,0) | J13: R1 | K13: 2 | L13: Primera regla de valor real para el editor.
A14: US-19 | B14: E. Revisión | C14: Ver cola de manuscritos pendientes | D14: 100 | E14: 1 | F14: 1 | G14: 0.5 | H14: =IF(G14>0,D14*E14*F14/G14,0) | I14: =RANK(H14,$H$5:$H$40,0) | J14: R1 | K14: 4
A15: US-28 | B15: G. Administración | C15: Registro de ejecución por manuscrito | D15: 100 | E15: 1 | F15: 1 | G15: 0.5 | H15: =IF(G15>0,D15*E15*F15/G15,0) | I15: =RANK(H15,$H$5:$H$40,0) | J15: R1 | K15: 4
A16: US-29 | B16: G. Administración | C16: Registro de consumo y latencia de Gemini | D16: 100 | E16: 0.5 | F16: 1 | G16: 0.25 | H16: =IF(G16>0,D16*E16*F16/G16,0) | I16: =RANK(H16,$H$5:$H$40,0) | J16: R2 | K16: — | L16: Sacada del plan el 29-sep (antes Sprint 4); queda en backlog R2.
A17: US-03 | B17: A. Recepción | C17: Obtener metadatos del envío (sección, título, idioma) | D17: 100 | E17: 1 | F17: 0.8 | G17: 0.5 | H17: =IF(G17>0,D17*E17*F17/G17,0) | I17: =RANK(H17,$H$5:$H$40,0) | J17: R1 | K17: 3
A18: US-08 | B18: B. Extracción | C18: Extraer lista de referencias | D18: 100 | E18: 2 | F18: 0.8 | G18: 1 | H18: =IF(G18>0,D18*E18*F18/G18,0) | I18: =RANK(H18,$H$5:$H$40,0) | J18: R1 | K18: 3 | L18: Alcance MVP: segmentación y numeración de entradas; parseo por campos en R2. (Replan 29-sep)
A19: US-15 | B19: D. Sugerencias | C19: Redactar sugerencia con Gemini | D19: 100 | E19: 2 | F19: 0.8 | G19: 1 | H19: =IF(G19>0,D19*E19*F19/G19,0) | I19: =RANK(H19,$H$5:$H$40,0) | J19: R1 | K19: 4
A20: US-20 | B20: E. Revisión | C20: Ver sugerencias con evidencia | D20: 100 | E20: 2 | F20: 0.8 | G20: 1 | H20: =IF(G20>0,D20*E20*F20/G20,0) | I20: =RANK(H20,$H$5:$H$40,0) | J20: R1 | K20: 4
A21: US-21 | B21: E. Revisión | C21: Aceptar / rechazar / editar sugerencia | D21: 100 | E21: 3 | F21: 0.8 | G21: 1.5 | H21: =IF(G21>0,D21*E21*F21/G21,0) | I21: =RANK(H21,$H$5:$H$40,0) | J21: R1 | K21: 5 | L21: Garantiza la revisión humana (RNF-01).
A22: US-24 | B22: F. Publicación | C22: Publicar comentario en discusión OJS | D22: 100 | E22: 3 | F22: 0.8 | G22: 1.5 | H22: =IF(G22>0,D22*E22*F22/G22,0) | I22: =RANK(H22,$H$5:$H$40,0) | J22: R1 | K22: 5 | L22: Cierra el ciclo con el autor.
A23: US-11 | B23: C. Validación | C23: Validar figuras: pie, numeración, orden (RE-23..25) | D23: 70 | E23: 2 | F23: 0.8 | G23: 1 | H23: =IF(G23>0,D23*E23*F23/G23,0) | I23: =RANK(H23,$H$5:$H$40,0) | J23: R1 | K23: 3 | L23: Alcance MVP: RE-23 y RE-24; RE-25 (mención en el texto) en R2. (Replan 29-sep)
A24: US-05 | B24: B. Extracción | C24: Detectar secciones IMRyD | D24: 100 | E24: 2 | F24: 0.5 | G24: 1 | H24: =IF(G24>0,D24*E24*F24/G24,0) | I24: =RANK(H24,$H$5:$H$40,0) | J24: R1 | K24: 3 | L24: Heurística sensible a PDFs mal estructurados. Alcance MVP: solo Resumen, Palabras clave y Referencias; diccionario completo de variantes en R2. (Replan 29-sep)
A25: US-18 | B25: D. Sugerencias | C25: Reintentos, límite de tokens y fallback | D25: 30 | E25: 2 | F25: 0.8 | G25: 0.5 | H25: =IF(G25>0,D25*E25*F25/G25,0) | I25: =RANK(H25,$H$5:$H$40,0) | J25: R1 | K25: 4 | L25: Alcance MVP: reintentos con backoff y fallback; presupuesto de tokens en R2. (Replan 29-sep)
A26: US-13 | B26: C. Validación | C26: Validar referencias IEEE (RE-44..49) | D26: 80 | E26: 3 | F26: 0.5 | G26: 1.5 | H26: =IF(G26>0,D26*E26*F26/G26,0) | I26: =RANK(H26,$H$5:$H$40,0) | J26: R1 | K26: 3 | L26: Alto valor pero parser IEEE complejo. Alcance MVP: RE-44, RE-46, RE-47 y RE-49; patrón IEEE por tipo (RE-45) y RE-48 en R2. (Replan 29-sep)
A27: US-27 | B27: F. Publicación | C27: Notificar al editor por correo OJS | D27: 100 | E27: 0.5 | F27: 0.8 | G27: 0.5 | H27: =IF(G27>0,D27*E27*F27/G27,0) | I27: =RANK(H27,$H$5:$H$40,0) | J27: R2 | K27: — | L27: Sacada del plan el 29-sep (antes Sprint 6); queda en backlog R2.
A28: US-02 | B28: A. Recepción | C28: Plugin OJS: hook al completar un envío | D28: 100 | E28: 3 | F28: 0.5 | G28: 2 | H28: =IF(G28>0,D28*E28*F28/G28,0) | I28: =RANK(H28,$H$5:$H$40,0) | J28: R1 | K28: 5 | L28: Alto esfuerzo e incertidumbre en OJS 3.1.2.1; imprescindible para el flujo real.
A29: US-22 | B29: E. Revisión | C29: Agregar sugerencia manual | D29: 40 | E29: 1 | F29: 0.8 | G29: 0.5 | H29: =IF(G29>0,D29*E29*F29/G29,0) | I29: =RANK(H29,$H$5:$H$40,0) | J29: R2 | K29: — | L29: Sacada del plan el 29-sep (antes Sprint 6); queda en backlog R2.
A30: US-26 | B30: F. Publicación | C30: Vincular comentario a versión del manuscrito | D30: 50 | E30: 1 | F30: 0.5 | G30: 0.5 | H30: =IF(G30>0,D30*E30*F30/G30,0) | I30: =RANK(H30,$H$5:$H$40,0) | J30: R2 | K30: —
A31: US-33 | B31: G. Administración | C31: Auditoría de decisiones editoriales | D31: 100 | E31: 0.25 | F31: 1 | G31: 0.5 | H31: =IF(G31>0,D31*E31*F31/G31,0) | I31: =RANK(H31,$H$5:$H$40,0) | J31: R3 | K31: —
A32: US-23 | B32: E. Revisión | C32: Marcar manuscrito como "sin observaciones" | D32: 10 | E32: 1 | F32: 1 | G32: 0.25 | H32: =IF(G32>0,D32*E32*F32/G32,0) | I32: =RANK(H32,$H$5:$H$40,0) | J32: R2 | K32: — | L32: Sacada del plan el 29-sep (antes Sprint 6); queda en backlog R2.
A33: US-30 | B33: G. Administración | C33: Editar reglas sin redespliegue | D33: 100 | E33: 0.5 | F33: 0.8 | G33: 1 | H33: =IF(G33>0,D33*E33*F33/G33,0) | I33: =RANK(H33,$H$5:$H$40,0) | J33: R2 | K33: —
A34: US-14 | B34: C. Validación | C34: Validar estructura, resumen y palabras clave (RE-01..15) | D34: 60 | E34: 1 | F34: 0.5 | G34: 1 | H34: =IF(G34>0,D34*E34*F34/G34,0) | I34: =RANK(H34,$H$5:$H$40,0) | J34: R2 | K34: — | L34: Sacada del plan el 29-sep (antes Sprint 3); queda en backlog R2.
A35: US-32 | B35: G. Administración | C35: Panel de métricas | D35: 100 | E35: 0.5 | F35: 0.8 | G35: 1.5 | H35: =IF(G35>0,D35*E35*F35/G35,0) | I35: =RANK(H35,$H$5:$H$40,0) | J35: R3 | K35: —
A36: US-31 | B36: A. Recepción | C36: Detectar reenvío (versión 2) | D36: 50 | E36: 1 | F36: 0.5 | G36: 1 | H36: =IF(G36>0,D36*E36*F36/G36,0) | I36: =RANK(H36,$H$5:$H$40,0) | J36: R2 | K36: —
A37: US-35 | B37: B. Extracción | C37: Detectar figuras recortadas / fuera de margen | D37: 30 | E37: 2 | F37: 0.5 | G37: 1.5 | H37: =IF(G37>0,D37*E37*F37/G37,0) | I37: =RANK(H37,$H$5:$H$40,0) | J37: R3 | K37: —
A38: US-25 | B38: F. Publicación | C38: Reintento y cola si OJS no responde | D38: 5 | E38: 2 | F38: 0.8 | G38: 0.5 | H38: =IF(G38>0,D38*E38*F38/G38,0) | I38: =RANK(H38,$H$5:$H$40,0) | J38: R2 | K38: — | L38: Sacada del plan el 29-sep (antes Sprint 6); queda en backlog R2.
A39: US-34 | B39: B. Extracción | C39: Detectar tablas y sus títulos | D39: 60 | E39: 0.5 | F39: 0.5 | G39: 1 | H39: =IF(G39>0,D39*E39*F39/G39,0) | I39: =RANK(H39,$H$5:$H$40,0) | J39: R3 | K39: —
A40: US-36 | B40: C. Validación | C40: Validar formato de página (RE-60..65) | D40: 40 | E40: 0.5 | F40: 0.5 | G40: 1.5 | H40: =IF(G40>0,D40*E40*F40/G40,0) | I40: =RANK(H40,$H$5:$H$40,0) | J40: R3 | K40: —
B42: Resumen
...

Sheet Sprint 1
A1: Sprint 1 — 14 al 25 de septiembre de 2026 (10 días hábiles)
A2: Sprint Goal: Contar con un walking skeleton local que reciba un PDF de Innosoft, extraiga texto y figuras, aplique las primeras reglas de figuras desde un archivo de reglas versionado y devuelva un JSON de incumplimientos con ubicación, con la especificación general del producto aprobada.
A4: Orden | B4: ID | C4: Historia | D4: Reglas | E4: Effort | F4: Responsable | G4: Criterios de aceptación | H4: Estado
A5: 1 | B5: US-00 | C5: Especificación general del producto y configuración del entorno (historia técnica) | D5: — | E5: 0.5 | F5: Ambos | G5: specs/00-producto.md aprobada por ambos; plantilla de spec; repositorio con CI; Docker Compose (FastAPI + PostgreSQL) arranca con un comando; 5 PDFs de prueba anonimizados; plantillas oficiales e innosoft.cls en docs/. | H5: Parcial
A6: 2 | B6: US-01 | C6: Recibir PDF por API | D6: — | E6: 0.25 | F6: Dev A | G6: POST /manuscripts acepta PDF ≤ 25 MB + metadatos y responde 202 con manuscript_id; 400 si no es PDF; 413 si excede tamaño; el archivo y el estado "received" quedan persistidos. | H6: Arrastrada
A7: 3 | B7: US-04 | C7: Extraer texto y páginas | D7: — | E7: 0.5 | F7: Dev A | G7: Salida JSON por página con bloques, bbox, fuente y tamaño; PDF sin capa de texto → estado "unreadable" y aviso (ALT-01); 30 páginas en menos de 10 s; persistido como JSONB. | H7: Arrastrada
A8: 4 | B8: US-09 | C8: Cargar reglas Innosoft desde YAML | D8: RE-20..27 definidas | E8: 0.5 | F8: Dev B | G8: Cada regla tiene id, categoría, descripción, condición, severidad, mensaje, sección y fuente; se valida contra JSON Schema al arrancar; regla inválida detiene el arranque con mensaje claro; GET /rules disponible. | H8: Arrastrada
A9: 5 | B9: US-06 | C9: Extraer figuras: posición, tamaño, pie | D9: — | E9: 0.75 | F9: Dev B | G9: Por cada imagen: página, bbox, px reales, dpi efectivo y pie asociado ("Figura n."); imágenes vectoriales marcadas como vector; manuscrito sin figuras devuelve lista vacía (ALT-03). | H9: Arrastrada
A10: 6 | B10: US-10 | C10: Validar figuras: tamaño y proporción | D10: RE-20, RE-21 | E10: 0.5 | F10: Dev B | G10: Motor run_rules tolerante a fallos por regla; hallazgos con rule_id, severidad, página, figura, encontrado y esperado; GET /manuscripts/{id}/findings; pruebas: figura 300×600 px falla RE-20, figura 800×2000 px a 300 dpi pasa. | H10: Arrastrada
A11: 7 | B11: US-07 | C11: Extraer citas en texto [n] (stretch) | D11: — | E11: 0.25 | F11: Dev A | G11: Se detectan [1], [3, 4], [1]–[5] con posición y puntuación adyacente; citas autor-año marcadas como candidatas. | H11: Arrastrada
C13: Effort comprometido | E13: =SUMIF(H5:H11,"Comprometida",E5:E11)
C14: Effort stretch | E14: =SUMIF(H5:H11,"Stretch",E5:E11)
C15: Effort arrastrado al Sprint 2 | E15: =SUMIF(H5:H11,"Arrastrada",E5:E11)
C16: Regla de recorte: si la capacidad real no alcanza, se recorta desde el orden mayor (US-10 primero). El Sprint Goal se cumple con US-00 a US-06 completas y RE-20 evaluándose.
C18: Definition of Done
C19: 1. La spec de la historia existe, fue revisada por el otro developer y coincide con lo implementado.
C20: 2. Pruebas Pytest en verde en GitHub Actions.
C21: 3. Código en main mediante pull request revisado.
C22: 4. Cada hallazgo devuelto tiene rule_id trazable a rules/*.yaml.
C23: 5. Demo reproducible con docker compose up + curl en la Sprint Review.
C25: Riesgos
C26: Riesgo | G26: Mitigación
C27: Figuras vectoriales en PDFs generados desde LaTeX no aparecen como imágenes | G27: Detectar también dibujos vectoriales (page.get_drawings) y marcarlos como vector; RE-21 no aplica a vectores
C28: Falta innosoft.cls y estilos internos del .docx | G28: Solicitarlos al equipo editorial; los valores de RE-20..27 se ajustan en YAML sin tocar código
C29: Capacidad real menor a la planificada | G29: Orden de prioridad explícito; US-10 primer recorte; US-07 stretch
C31: Resultado del Sprint 1 (registrado el 29-sep-2026)
C32: • Sprint Goal no cumplido: no se implementó el walking skeleton (0 de 38 tareas de código).
C33: • Sí se produjo: catálogo de requisitos v1.0, priorización RICE, diagramas de clases y despliegue (18-sep).
C34: • Tras el cierre (29-sep): borradores de 00-producto.md, formato-reglas.md, _template.md y specs US-00..US-36.
C35: • US-00 queda Parcial (specs sin aprobar; sin repositorio, CI, Docker ni corpus). Todo lo demás se arrastra al Sprint 2.
C36: • US-07 (stretch) pasa al Sprint 3.

Sheet Tareas Sprint 1
A1: Sprint Backlog — Tareas del Sprint 1
A2: Actualice la columna Estado durante el sprint. El avance se calcula automáticamente.
A4: # | B4: Historia | C4: Tarea | D4: Responsable | E4: Estado | F4: Notas
A5: 1 | B5: US-00 | C5: Redactar specs/00-producto.md: objetivo, actores, alcance, entradas/salidas, RNF-01..07, ALT-01..12 | D5: Ambos | E5: Hecho | F5: Borrador v0.1 del 29-sep; falta aprobación de ambos
A6: 2 | B6: US-00 | C6: Redactar specs/formato-reglas.md con JSON Schema de regla y ejemplo RE-20 | D6: Dev B | E6: Hecho | F6: Borrador v0.1 del 29-sep; JSON Schema validado
A7: 3 | B7: US-00 | C7: Crear repositorio GitHub con estructura app/, specs/, rules/, prompts/, tests/, docs/ | D7: Dev A | E7: Pendiente | F7: Pasa al Sprint 2
A8: 4 | B8: US-00 | C8: Docker Compose con FastAPI + PostgreSQL; README con arranque en un comando | D8: Dev A | E8: Pendiente | F8: Pasa al Sprint 2
A9: 5 | B9: US-00 | C9: Configurar GitHub Actions con Pytest | D9: Dev A | E9: Pendiente | F9: Pasa al Sprint 2
A10: 6 | B10: US-00 | C10: Crear plantilla specs/_template.md (propósito, entradas, salidas, reglas, excepciones, AC, pruebas) | D10: Dev B | E10: Hecho | F10: specs/_template.md creado el 29-sep
A11: 7 | B11: US-00 | C11: Reunir 5 PDFs de prueba anonimizados: 2 con figuras problemáticas, 1 sin figuras, 1 escaneado, 1 correcto | D11: Ambos | E11: Pendiente | F11: Pasa al Sprint 2
A12: 8 | B12: US-00 | C12: Guardar en docs/ las plantillas Word y LaTeX oficiales e innosoft.cls | D12: Dev B | E12: Pendiente | F12: Pasa al Sprint 2
A13: 9 | B13: US-01 | C13: Escribir specs/US-01.md | D13: Dev A | E13: Hecho | F13: Borrador v0.1 del 29-sep en specs/; falta revisión cruzada
A14: 10 | B14: US-01 | C14: Modelo Manuscript (id, filename, sección, estado, created_at) y migración | D14: Dev A | E14: Pendiente | F14: Pasa al Sprint 2
A15: 11 | B15: US-01 | C15: Endpoint POST /manuscripts multipart con validación MIME y tamaño | D15: Dev A | E15: Pendiente | F15: Pasa al Sprint 2
A16: 12 | B16: US-01 | C16: Almacenamiento en storage/{id}.pdf | D16: Dev A | E16: Pendiente | F16: Pasa al Sprint 2
... A42: 38 | B42: US-07 | C42: Detectar citas autor-año como candidatas | D42: Dev A | E42: Pendiente | F42: Pasa al Sprint 3
C44: Avance del sprint
C45: Tareas totales | D45: =COUNTA(C5:C42)
C46: Tareas hechas | D46: =COUNTIF(E5:E42,"Hecho")
C47: Tareas bloqueadas | D47: =COUNTIF(E5:E42,"Bloqueada")
C48: % avance | D48: =IF(D45>0,D46/D45,0)
C50: Avance por historia
C51: US-00 | D51: =IF(COUNTIF(B5:B42,C51)>0,COUNTIFS(B5:B42,C51,E5:E42,"Hecho")/COUNTIF(B5:B42,C51),0)
C52: US-01 | D52: =IF(COUNTIF(B5:B42,C52)>0,COUNTIFS(B5:B42,C52,E5:E42,"Hecho")/COUNTIF(B5:B42,C52),0)
C53: US-04 | D53: =IF(COUNTIF(B5:B42,C53)>0,COUNTIFS(B5:B42,C53,E5:E42,"Hecho")/COUNTIF(B5:B42,C53),0)
C54: US-09 | D54: =IF(COUNTIF(B5:B42,C54)>0,COUNTIFS(B5:B42,C54,E5:E42,"Hecho")/COUNTIF(B5:B42,C54),0)
C55: US-06 | D55: =IF(COUNTIF(B5:B42,C55)>0,COUNTIFS(B5:B42,C55,E5:E42,"Hecho")/COUNTIF(B5:B42,C55),0)
C56: US-10 | D56: =IF(COUNTIF(B5:B42,C56)>0,COUNTIFS(B5:B42,C56,E5:E42,"Hecho")/COUNTIF(B5:B42,C56),0)
C57: US-07 | D57: =IF(COUNTIF(B5:B42,C57)>0,COUNTIFS(B5:B42,C57,E5:E42,"Hecho")/COUNTIF(B5:B42,C57),0)

Sheet Sprint 2
A1: Sprint 2 — 28 de septiembre al 9 de octubre de 2026 (replanificado el 29-sep; 8 días hábiles restantes)
A2: Sprint Goal: Contar con un walking skeleton en Docker que reciba un PDF de Innosoft, extraiga texto y figuras, aplique RE-20 y RE-21 desde rules/innosoft/figuras.yaml y devuelva un JSON de incumplimientos con ubicación, con las specs del sprint aprobadas. (Objetivo original del Sprint 1.)
A4: Orden | B4: ID | C4: Historia | D4: Reglas | E4: Effort | F4: Responsable | G4: Criterios de aceptación | H4: Estado
A5: 1 | B5: US-00 | C5: Aprobación de specs y configuración del entorno (resto de la historia técnica) | D5: — | E5: 0.5 | F5: Ambos | G5: 00-producto.md, formato-reglas.md y specs del sprint aprobadas por ambos (hecho); repositorio con CI; Docker Compose (agent-api y PostgreSQL) arranca con un comando; 5 PDFs de prueba anonimizados; plantillas oficiales e innosoft.cls en docs/. | H5: Comprometida
A6: 2 | B6: US-01 | C6: Recibir PDF por API | D6: — | E6: 0.25 | F6: Dev A | G6: POST /manuscripts acepta PDF ≤ 25 MB + metadatos y responde 202 con manuscript_id; 400 si no es PDF; 413 si excede tamaño; el archivo y el estado "received" quedan persistidos; reenvío idéntico → 200 con el manuscript_id existente (D-01). | H6: Comprometida
A7: 3 | B7: US-04 | C7: Extraer texto y páginas | D7: — | E7: 0.5 | F7: Dev A | G7: Salida JSON por página con bloques, bbox, fuente y tamaño; PDF sin capa de texto → estado "unreadable" y aviso (ALT-01); 30 páginas en menos de 10 s; persistido como JSONB. | H7: Comprometida
A8: 4 | B8: US-09 | C8: Cargar reglas Innosoft desde YAML | D8: RE-20..27 definidas | E8: 0.5 | F8: Dev B | G8: Cada regla tiene id, categoría, descripción, condición, severidad, mensaje, sección y fuente; se valida contra JSON Schema al arrancar; regla inválida detiene el arranque con mensaje claro; GET /rules disponible. | H8: Comprometida
A9: 5 | B9: US-06 | C9: Extraer figuras: posición, tamaño, pie | D9: — | E9: 0.75 | F9: Dev B | G9: Por cada imagen: página, bbox, px reales, dpi efectivo y pie asociado ("Figura n."); imágenes vectoriales marcadas como vector; manuscrito sin figuras devuelve lista vacía (ALT-03). | H9: Comprometida
A10: 6 | B10: US-10 | C10: Validar figuras: tamaño y proporción | D10: RE-20, RE-21 | E10: 0.5 | F10: Dev B | G10: Motor run_rules tolerante a fallos por regla; hallazgos con rule_id, severidad, página, figura, encontrado y esperado; GET /manuscripts/{id}/findings; pruebas: figura 300×600 px falla RE-20, figura 800×2000 px a 300 dpi pasa. | H10: Comprometida
C13: Effort comprometido | E13: =SUMIF(H5:H10,"Comprometida",E5:E10)
C14: Effort stretch | E14: =SUMIF(H5:H10,"Stretch",E5:E10)
C15: Effort terminado | E15: =SUMIF(H5:H10,"Hecha",E5:E10)
C16: Regla de recorte: si el martes 6-oct US-01 y US-04 no están en main, US-06 se limita a figuras raster y US-10 a RE-20. El Sprint Goal se cumple con US-00, US-01, US-04, US-09 y US-06 completas y RE-20 evaluándose.
C18: Definition of Done
C19: 1. La spec de la historia existe, fue revisada por el otro developer y coincide con lo implementado.
C20: 2. Pruebas Pytest en verde en GitHub Actions.
C21: 3. Código en main mediante pull request revisado.
C22: 4. Cada hallazgo devuelto tiene rule_id trazable a rules/*.yaml.
C23: 5. Demo reproducible con docker compose up + curl en la Sprint Review.
C25: Riesgos
C26: Riesgo | G26: Mitigación
C27: Figuras vectoriales en PDFs generados desde LaTeX no aparecen como imágenes | G27: Detectar también dibujos vectoriales (page.get_drawings) y marcarlos como vector; RE-21 no aplica a vectores
C28: Falta innosoft.cls y estilos internos del .docx | G28: Solicitarlos al equipo editorial; los valores de RE-20..27 se ajustan en YAML sin tocar código
C29: Capacidad real menor a la planificada (el Sprint 1 no produjo código) | G29: Mismo effort que el Sprint 1 (3,0) en 8 días; punto de control el 6-oct; US-10 primer recorte
C30: Repetir el patrón del Sprint 1: quedarse en documentación | G30: Timebox: specs aprobadas el 30-sep; desde el 1-oct solo código. Cambios de spec, por PR pequeño.
C31: Procesamiento asíncrono | G31: Decisión D-04: BackgroundTasks de FastAPI en esta etapa; Celery + Redis en una fase posterior sin cambiar la API

Sheet Tareas Sprint 2
A1: Sprint Backlog — Tareas del Sprint 2 (replanificado el 29-sep-2026)
A2: Actualice la columna Estado durante el sprint. El avance se calcula automáticamente.
A4: # | B4: Historia | C4: Tarea | D4: Responsable | E4: Estado | F4: Notas
A5: 1 | B5: US-00 | C5: Revisar y aprobar specs/00-producto.md y specs/formato-reglas.md (fecha límite 30-sep) | D5: Ambos | E5: Hecho | F5: Aprobadas v1.0 (decisiones D-01..D-04)
A6: 2 | B6: US-00 | C6: Revisión cruzada y aprobación de specs US-01, US-04, US-06, US-09, US-10 (fecha límite 30-sep) | D6: Ambos | E6: Hecho | F6: Aprobadas v1.0
A7: 3 | B7: US-00 | C7: Crear repositorio GitHub con app/, specs/, rules/, prompts/, tests/, docs/ y subir specs y diagramas | D7: Dev A | E7: Hecho
A8: 4 | B8: US-00 | C8: Docker Compose con agent-api (FastAPI) y PostgreSQL; README con arranque en un comando (Celery + Redis en una fase posterior, D-04) | D8: Dev A | E8: Hecho
A9: 5 | B9: US-00 | C9: Configurar GitHub Actions con Pytest y protección de main | D9: Dev A | E9: Hecho
A10: 6 | B10: US-00 | C10: Reunir 5 PDFs de prueba anonimizados: 2 con figuras problemáticas, 1 sin figuras, 1 escaneado, 1 correcto | D10: Ambos | E10: Hecho
A11: 7 | B11: US-00 | C11: Guardar en docs/ las plantillas Word y LaTeX oficiales e innosoft.cls | D11: Dev B | E11: Hecho
A12: 8 | B12: US-00 | C12: Consultar a la revista la regla panorámica de RE-20 (no bloqueante: se aprobó el supuesto 531 × 1328 px, D-03) y los section_id de las 3 secciones en OJS | D12: Ambos | E12: Pendiente
A13: 9 | B13: US-01 | C13: Modelo Manuscript (id, submission_id, sha256, sección, estado, created_at) y migración Alembic | D13: Dev A | E13: Hecho
A14: 10 | B14: US-01 | C14: Endpoint POST /manuscripts multipart con validación de firma %PDF-, tamaño y metadatos | D14: Dev A | E14: Hecho
A15: 11 | B15: US-01 | C15: Almacenamiento en storage/{id}.pdf, idempotencia por submission_id + sha256 (D-01) y lanzamiento del análisis con BackgroundTasks (D-04) | D15: Dev A | E15: Hecho
A16: 12 | B16: US-01 | C16: Pytest: PDF válido → 202; no PDF → 400; > 25 MB → 413; sin submission_id → 422; reenvío idéntico → 200 con el mismo manuscript_id | D16: Dev A | E16: Hecho
A17: 13 | B17: US-04 | C17: Servicio extract_text(pdf) → Document con PyMuPDF (bloques, bbox, fuente, tamaño, negrita/cursiva) | D17: Dev A | E17: Hecho
A18: 14 | B18: US-04 | C18: Detección de PDF sin texto o corrupto → estado unreadable (ALT-01) | D18: Dev A | E18: Hecho
... A34: 30 | B34: US-10 | C34: Guion de demo: docker compose up + curl POST y GET findings (Sprint Review 9-oct) | D34: Ambos | E34: Hecho
C36: Avance del sprint
C37: Tareas totales | D37: =COUNTA(C5:C34)
C38: Tareas hechas | D38: =COUNTIF(E5:E34,"Hecho")
C39: Tareas bloqueadas | D39: =COUNTIF(E5:E34,"Bloqueada")
C40: % avance | D40: =IF(D37>0,D38/D37,0)
C42: Avance por historia
C43: US-00 | D43: =IF(COUNTIF($B$5:$B$34,C43)>0,COUNTIFS($B$5:$B$34,C43,$E$5:$E$34,"Hecho")/COUNTIF($B$5:$B$34,C43),0)
C44: US-01 | D44: =IF(COUNTIF($B$5:$B$34,C44)>0,COUNTIFS($B$5:$B$34,C44,$E$5:$E$34,"Hecho")/COUNTIF($B$5:$B$34,C44),0)
C45: US-04 | D45: =IF(COUNTIF($B$5:$B$34,C45)>0,COUNTIFS($B$5:$B$34,C45,$E$5:$E$34,"Hecho")/COUNTIF($B$5:$B$34,C45),0)
C46: US-09 | D46: =IF(COUNTIF($B$5:$B$34,C46)>0,COUNTIFS($B$5:$B$34,C46,$E$5:$E$34,"Hecho")/COUNTIF($B$5:$B$34,C46),0)
C47: US-06 | D47: =IF(COUNTIF($B$5:$B$34,C47)>0,COUNTIFS($B$5:$B$34,C47,$E$5:$E$34,"Hecho")/COUNTIF($B$5:$B$34,C47),0)
C48: US-10 | D48: =IF(COUNTIF($B$5:$B$34,C48)>0,COUNTIFS($B$5:$B$34,C48,$E$5:$E$34,"Hecho")/COUNTIF($B$5:$B$34,C48),0)

Sheet Calendario
A1: Calendario de sprints (2 semanas)
A2: Replanificado el 29-sep-2026: el Sprint 1 no produjo código y su objetivo pasa al Sprint 2. Feriado nacional: jueves 8-oct.
A3: Sprint | B3: Inicio | C3: Fin | D3: Tema (Capítulo III) | E3: Historias candidatas | F3: Días hábiles | H3: Feriados
A4: 1 | B4: 46279 | C4: 46290 | D4: Especificación general y base del sistema | E4: Plan: US-00, US-01, US-04, US-09, US-06, US-10 (US-07 stretch). Resultado: solo especificación y diseño; la implementación se arrastra al Sprint 2. | F4: =NETWORKDAYS(B4,C4,$H$4:$H$5) | H4: 46303 | I4: Combate de Angamos (feriado nacional)
A5: 2 | B5: 46293 | C5: 46304 | D5: Walking skeleton (objetivo original del Sprint 1) | E5: US-00, US-01, US-04, US-09, US-06, US-10. Specs aprobadas el 30-sep; desde el 1-oct solo código. | F5: =NETWORKDAYS(B5,C5,$H$4:$H$5) | H5: 46364 | I5: Inmaculada Concepción (fuera del calendario, referencia)
A6: 3 | B6: 46307 | C6: 46318 | D6: Procesamiento documental y reglas de citas y referencias | E6: US-03, US-05*, US-07, US-08*, US-11*, US-12, US-13* + spike API REST OJS 3.1.2.1 (1 día). * alcance reducido | F6: =NETWORKDAYS(B6,C6,$H$4:$H$5)
A7: 4 | B7: 46321 | C7: 46332 | D7: Integración de Gemini e inicio de la interfaz editorial | E7: US-17, US-15, US-16, US-18*, US-28, US-19, US-20; matriz de trazabilidad y OpenAPI | F7: =NETWORKDAYS(B7,C7,$H$4:$H$5)
A8: 5 | B8: 46335 | C8: 46346 | D8: Revisión editorial e integración con OJS | E8: US-21, US-24, US-02. Si el 16-nov US-02 no avanza: disparo manual vía POST /manuscripts y se mantiene US-24. | F8: =NETWORKDAYS(B8,C8,$H$4:$H$5)
A9: 6 | B9: 46349 | C9: 46360 | D9: Evaluación, ajustes y versión final | E9: Sin historias nuevas: 3 días de buffer, métricas (precisión, recall, F1, tasa de aceptación), manuales y capítulo de resultados. US-23 solo si sobra capacidad. | F9: =NETWORKDAYS(B9,C9,$H$4:$H$5)
A12: Eventos Scrum del Sprint 1
A13: Evento | B13: Fecha | C13: Duración | D13: Objetivo
A14: Sprint Planning | B14: 46279 | C14: 2 h | D14: Confirmar capacidad, re-estimar historias, definir Sprint Backlog
A15: Daily Scrum | B15: Diario | C15: 15 min | D15: Sincronización y detección de impedimentos
A16: Refinamiento del backlog | B16: 46288 | C16: 1 h | D16: Preparar historias del Sprint 2 (US-05, 07, 08, 11, 12, 13)
A17: Sprint Review | B17: 46290 | C17: 1 h | D17: Demo del walking skeleton; revisión de specs
A18: Sprint Retrospective | B18: 46290 | C18: 45 min | D18: Claridad de specs, distribución del trabajo, configuración, estimaciones
A20: Eventos Scrum del Sprint 2 (replanificado)
A21: Evento | B21: Fecha | C21: Duración | D21: Objetivo
A22: Replanificación | B22: 46294 | C22: 1 h | D22: Aceptar el nuevo plan, recortes y regla de recorte (hoja 'Replan 29-sep')
A23: Aprobación de specs | B23: 46295 | C23: 2 h | D23: Revisión cruzada de 00-producto, formato-reglas y US-00/01/04/06/09/10
A24: Daily Scrum | B24: Diario | C24: 15 min | D24: Sincronización; ¿hay código en main desde ayer?
A25: Punto de control | B25: 46301 | C25: 30 min | D25: US-01 y US-04 en main; si no, aplicar regla de recorte del Sprint 2
A26: Refinamiento del backlog | B26: 46302 | C26: 1 h | D26: Preparar Sprint 3 (US-03, 05, 07, 08, 11, 12, 13) y el spike de OJS
A27: Sprint Review | B27: 46304 | C27: 1 h | D27: Demo del walking skeleton con docker compose up + curl
A28: Sprint Retrospective | B28: 46304 | C28: 45 min | D28: Por qué el Sprint 1 no produjo código; acuerdos de capacidad real
